1. 运行时恐慌 panic
只会在程序运行的时候被抛出来
当 panic 被抛出之后，如果我们没有在程序里添加任何保护措施的话，
    程序（或者说代表它的那个进程）就会在打印出 panic 的详细情况（以下简称 panic 详情）之后，终止运行
2. 从 panic 被引发到程序终止运行的大致过程是什么
panic 详情会在控制权传播的过程中，被逐渐地积累和完善，并且，控制权会一级一级地沿着调用栈的反方向传播至顶端。
    当控制权传播到顶端的时候，程序就会停止运行，并且 panic 详情会被打印出来
这里的最外层函数指的是go函数，对于主 goroutine 来说就是main函数。但是控制权也不会停留在那里，而是被 Go 语言运行时系统收回。
随后，程序崩溃并终止运行，承载程序这次运行的进程也会随之死亡并消失。
    与此同时，在这个控制权传播的过程中，panic 详情会被逐渐地积累和完善，并会在程序终止之前被打印出来。
3. panic 和 error的区别
panic代表着特殊的（或者说意外的）错误，error代表着普通的错误。
    与try-catch不同，error并不是打断正常的控制流程的执行。单单这一点来讲，就已经是非常好的进步了。
    相比之下，panic会打断正常的控制流程
4. 怎样让 panic 包含一个值，以及应该让它包含什么样的值
panic(fmt.Sprintf("test panic")) // panic: test panic
5. 怎样施加应对 panic 的保护措施，从而避免程序崩溃？
Go 语言的内建函数recover专用于恢复 panic，或者说平息运行时恐慌。
    recover函数无需任何参数，并且会返回一个空接口类型的值。
无论函数结束执行的原因是什么，其中的defer函数调用都会在它即将结束执行的那一刻执行。
    即使导致它执行结束的原因是一个 panic 也会是这样。
    尽量把defer语句写在函数体的开始处
func testRecover() {
	fmt.Println("testRecover")

	defer func() {
		fmt.Println("Enter defer function.")
		if p := recover(); p != nil {
			fmt.Printf("panic: %s\n", p)
		}
		fmt.Println("Exit defer function.")
	}()
	panic(errors.New("something wrong"))
	fmt.Println("Exit testRecover")
}
6. 如果一个函数中有多条defer语句，那么那几个defer函数调用的执行顺序是怎样的
defer函数调用的执行顺序与它们分别所属的defer语句的出现顺序（更严谨地说，是执行顺序）完全相反。
在defer语句每次执行的时候，Go 语言会把它携带的defer函数及其参数值另行存储到一个链表中。
    这个链表与该defer语句所属的函数是对应的，并且，它是先进后出（FILO）的，相当于一个栈。
        在需要执行某个函数中的defer函数调用的时候，Go 语言会先拿到对应的链表，
        然后从该链表中一个一个地取出defer函数及其参数值，并逐个执行调用。
    当所有的defer函数调用都执行完毕后，Go 语言会把链表中的所有defer函数及其参数值都清空
7. 我们可以在defer函数中恢复 panic，那么可以在其中引发 panic 吗
可以， 因为在defer函数中，可以恢复 panic，并且可以把它携带的值传递给调用它的函数。

